Workbook
Name PM: '[1]DNC People '!$B$4:$B$12
Name SMSPM: '[1]DNC People '!$E$4:$E$7

Sheet DASHBOARD
A1: Subsidiary | B1: # of Active Projects | C1: Total Active Approved Capital | D1: # of Development Projects
A2: THS | B2: =#REF! -> #REF! | C2: =#REF! -> #REF! | D2: ='Design & Development'!#REF! -> #REF!
A3: Gaming | B3: =GAMING!A38 -> 21 | C3: =GAMING!L38 -> 138580668 | D3: ='Design & Development'!A12 -> #REF!
A4: Parks | B4: =PARKS!A27 -> 10 | C4: =PARKS!L27 -> 53785409 | D4: ='Design & Development'!A6 -> #REF!
A5: Patina | B5: =PATINA!A19 -> 7 | C5: =PATINA!L10 -> 909990 | D5: ='Design & Development'!A14 -> 11
A6: SS | B6: =SS!A4 -> 0 | C6: =SS!L4 -> 0 | D6: ='Design & Development'!A2 -> 1
B7: =SUM(B2:B6) -> #REF! | C7: =SUM(C2:C6) -> #REF! | D7: =SUM(D2:D6) -> #REF!

Sheet Sheet1
A1: Subsidiary | B1: # of Active Projects | C1: Total Active Approved Capital | D1: # of Development Projects
A2: Gaming | B2: =GAMING!A38 -> 21 | C2: =GAMING!L38 -> 138580668 | D2: ='Design & Development'!A12 -> #REF!
A3: Parks | B3: =PARKS!A27 -> 10 | C3: =PARKS!L27 -> 53785409 | D3: ='Design & Development'!A6 -> #REF!
A4: Patina | B4: =PATINA!A19 -> 7 | C4: =PATINA!L10 -> 909990 | D4: ='Design & Development'!A14 -> 11
A5: SS | B5: =SS!A4 -> 0 | C5: =SS!L4 -> 0 | D5: ='Design & Development'!A2 -> 1
B6: =SUM(B2:B5) -> 38 | C6: =SUM(C2:C5) -> 193276067 | D6: =SUM(D2:D5) -> #REF!

Sheet CORP
A1: Project Name | B1: CAPP # | C1: PM | D1: Project Update | E1: Previous Week Update | F1: Budget Risk | G1: Schedule Risk | H1: A & E / Pre-Con Capp | I1: Construction Capp | J1: Add-CAPP (Cumulative) | K1: Total Approved Budget | L1: Anticipated Final Cost | M1: Budget / Final Cost Variance | N1: % Variance | O1: Original Start Date | P1: Current Start Date | Q1: Original Turnover Date To Ops | R1: Current Turnover Date To Ops | S1: Duration Change
A2: 250 Delaware Ave
A3: 3 office build out "Transformation Dept" | B3: 08727 | C3: Matt Nowakowski | D3: completed. turn over was 8/30 to dept | E3: Capp Approved | H3: 4900 | I3: 68460 | K3: 72000 | L3: 68460 | O3: 46195 | P3: 46195 | Q3: 46223 | R3: 46223
A4: 10th FL lobby re-flooring | B4: 08728 | C4: Matt Nowakowski | D4: materials shipped from Italy 4-6 lead time via boat, early Oct install | E4: Capp Approved | I4: 123891 | L4: 123891 | O4: 46266 | P4: 46266 | Q4: 46266 | R4: 46287
A5: Highmark Stadium - DN Suite
A6: DN Suite Pantry | B6: 63541 | C6: Joe Quagliana | D6: Food service equipment delivery and set in place is scheduled for Wednesday 9/2. Bills have responded that upgrades to electrical will not be approved in the short term. This leaves leaves the Turbochefs unpowered and no additional accent lighting fron of house. | E6: Food service equipment has been ordered. Delivery scheduled for next week. Arc is working with the Bills to get electrical modifications approved. Electrical work will happen quickly once approval is received. | F6: High | G6: High | H6: 0 | I6: 143336.8 | J6: 313028 | L6: 456365 | P6: 46274
A7: KeyBank Center - DN Suite
A8: DN Suite Remodel | B8: 8736 | C8: Joe Quagliana/Matt Nowakowski | D8: CAPP approved. Millwork shop drawings reviewed and approved. GC Scheduled. Deposit for millwork & reach-in being submitted. Project currently on schedule to be completed by 10/3 opening game. | E8: CAPP submitted. Layout finalized. GC Scheduled. Deposit for millwork & reach-in being submitted. Project appears to be on schedule to be completed by 10/3 opening game. | F8: low | G8: low | H8: 0 | I8: 242900 | J8: 0 | K8: 242900 | L8: 242900 | O8: 46235 | Q8: 46296

Sheet PATINA
A1: Count | B1: Project Name | C1: CAPP # | D1: PM | E1: Project Update | F1: Previous Week Update | G1: Budget Risk | H1: Schedule Risk | I1: A & E / Pre-Con Capp | J1: Construction Capp | K1: Add-CAPP (Cumulative) | L1: Total Approved Budget | M1: Anticipated Final Cost | N1: Budget / Final Cost Variance | O1: % Variance | P1: Original Start Date | Q1: Current Start Date | R1: Original Turnover Date To Ops | S1: Current Turnover Date To Ops | T1: Duration Change
B2: Morimoto
A3: 1 | B3: Stairwell replacement in the back of house | C3: 8717 | D3: David Ruede | E3: Await an overall schedule. The staircase itself to be completed on 9/22. Permit has been approved, but not pulled yet so the clock doesn't start ticking. Sage Schultz and Hamid Igliou will now be the leads on this for Disney. | F3: Await a schedule. Permit has been approved but not pulled yet. Sage Schultz and Hamid Igliou will now be the leads on this for Disney. | I3: N/A | J3: 272030 | L3: =SUM(I3:K3) -> 272030 | M3: 272030 | N3: =IFERROR(M3-L3,"0") -> 0 | P3: 46106 | R3: 46280
B4: Hundredfold - Truist Park, Atlanta
A5: 1 | B5: New Restaurant | C5: 8687 | D5: David Ruede | E5: Exhaust Hoods are hung. Overhead ceiling getting completed. Sprinkler rough-in is on-going. Beer Cooler installed by Singer and the other walk-in coolers are being installed. Electric Shut-down of the building has been scheduled with the Braves for Saturday, September 19th....anticipate Permanent Power on Monday, 9/21. | F5: Exterior Steel install continued. FRP install kitchen continued. MAU units were hung. PCU's were delivered and set on mezzanine in kitchen. Threaded rod for bar ceiling was installed. Plumbing rough in is complete. Lightinng rough in in hard ceiling is complete. Gas piping install is completed. Grease duct was delivered and install is on going. Electricians pulled wire to panels. | I5: 637960 | L5: =SUM(I5:K5) -> 637960 | M5: 637960 | N5: =IFERROR(M5-L5,"0") -> 0 | P5: 46175 | R5: 46327 | S5: 46327
B6: Hub Hall
A7: 1 | B7: Tacos Mejor (conversion of Taqueria & Cussers) | C7: 8730 | D7: David Ruede | E7: Permit in hand (9/8). A pre-construction meeting is required in advance of starting work which is scheduled for 9/15, therefore pushing start date to 9/16. Work to take place overnight. We need an Electrical & Plumbing Inspection before calling for the Final Bldg Inspection. Completion targeted for 10/2, though could slip if Inspectors are slow in responding. | F7: Permit in hand (9/8). Work to take place from 9/14 - 9/28, the majority of which will be overnight. | I7: N/A | J7: 0 | L7: =SUM(I7:K7) -> 0 | M7: 0 | N7: =IFERROR(M7-L7,"0") -> 0 | P7: tbd
B8: Izakaya at DTD - Anaheim
A9: 1 | B9: New restaurant concept (takeover) | C9: 8740 | D9: David Ruede | E9: CAPP approved for Schematic Design Only. Expect to be presenting to Disney in early October. | I9: 82289
B10: TOTAL | I10: =SUM(I2:I9) -> 720249 | J10: =SUM(J2:J9) -> 272030 | K10: =SUM(K2:K9) -> 0 | L10: =SUM(L2:L9) -> 909990 | M10: =SUM(M2:M9) -> 909990 | N10: =SUM(N2:N9) -> 0 | O10: =IFERROR((M10-L10)/L10,"No Input") -> 0
A11: 1
A14: 1
A16: 1
A19: =SUM(A2:A16) -> 7

Sheet THS Openings Chart
A1: Instructions
A2: Click on table below
A3: Go to PivotTable Analyze option on top bar/ribbon
A4: Click refresh
A5: You may have to right click on Current Turnover date and sort greatest to lowest
A7: Current Turnover Date To Ops | B7: (Multiple Items)
A9: Row Labels | B9: Sum of Current Turnover Date To Ops | C9: Sum of Current Start Date
A10: BOI Bardenay | B10: 45957 | C10: 45853
A11: BOI Starbucks | B11: 45922 | C11: 45817
A12: BOI Wendy's | B12: 45908 | C12: 45797
A13: BOI Flying M Coffee | B13: 45870 | C13: 45779
A14: BOI Form & Function | B14: 45869 | C14: 45785
A15: BOI Idaho Tap House | B15: 45835 | C15: 45716
A16: DEN - Denver Street Eats - New Concept | B16: 45826 | C16: 45665
A17: DTW 7 Greens & Wahlburgers | B17: 45818 | C17: 45698
A18: ATL Modern Market | B18: 45809 | C18: 45323
A19: BOI Pizza Hut | B19: 45806 | C19: 45709
A20: BOI Blue Sky Bagels | B20: 45806 | C20: 45709
A21: BOI Protein Bar | B21: 45806 | C21: 45709
... A34: Grand Total | B34: 1099057 | C34: 1095931

Sheet GAMING
A1: Count | B1: Project Name | C1: CAPP # | D1: PM | E1: Project Update | F1: Previous Week Update | G1: Budget Risk | H1: Schedule Risk | I1: A & E / Pre-Con Capp | J1: Construction Capp | K1: Add-CAPP (Cumulative) | L1: Total Approved Budget | M1: Anticipated Final Cost | N1: Budget / Final Cost Variance | O1: % Variance | P1: Original Start Date | Q1: Current Start Date | R1: Original Turnover Date To Ops | S1: Current Turnover Date To Ops | T1: Duration Change
B2: TWO KINGS
A3: 1 | B3: Two Kings Casino | C3: 08312 | D3: Kevin Keens | E3: - Podium Area 'A': Permanent chillers are expected to be on-line and functional this week. As reported during the 09/09 OAC meeting, YM will publish a revised construction schedule this week to include a recovery plan that details how the original 02/19 TCO date can be met for the podium. Daily coordination meetings occured last week to resolve outstanding millwork and decorative lighting design issues, both of which YM has reported to be the primary cause for schedule delay. Electrical rough-in and MEP install on BOH and casino levels 80% complete. Epoxy flooring has started on the BOH level. Wall finishes on BOH level in progress. Parking garage P3 level fire alarm, sprkinler, camera install 95% complete. - Podium Area 'B': Raised access flooring is now completed. Electrical rough-in and MEP install on the BOH and main casino levels 80% complete. Epoxy flooring has started on the BOH level. Wall finishes on BOH level in progress. Parking garage P3 level fire alarm, sprkinler, and camera install 95% complete. - Podium Area 'C': BOH and perm. casino level drywall finishing, ductwork, and plumbing fixture install in progress. Placement for permanent casino level non-specialty lighting is in progress. Ceiling completion on the BOH level is approx. 80%. - Hotel: TCO is scheduled for 05/26. Stud framing and door frame install awaiting inspections. Electrical rough-in on T-21. Plumbing rough-in completed thru T-20 and plumbing risers completed through T-25. Guestroom wall sheet rock starting on T-17. Ceiling mud float currently on T-23. Non-guestroom drywall install T-24. Elevators #1 & 2 frame build at 40% complete. Wall paint on T-6, wall tile install on T-5, wallcovering install on T-2. Laundry chute install has started. | F3: - Podium Area 'A': As reported during the 08/19 OAC, permanent power has been energized to the site and the process to bring on the permanent chillers started yesterday. This process can take a couple of weeks from start to finish. Per YM's most recent published revised construction schedule, substantial completion for the podium has been pushed to late-March and the hotel substantial completion is late-May. YM claims that the posted substantial completion schedule date for the podium is inaccurate and 02/19 is still the targeted date. Electrical rough-in on BOH level is 75% complete. Perm. casino and BOH level walls, ceilings, and soffits are ready for paint. - Podium Area 'B': Dewatering of previously reported column cavities continues to inch forward. The structural engineer will be on-site to perform an assessment once the final column has been drained and completely dried. Ductwork, plumbing install, and ceiling activities nearing completion. Electrical rough-in install on the BOH level is 80% completed. Perm. casino and BOH level walls, ceilings, and soffits are ready for paint. - Podium Area 'C': BOH and perm. casino level drywall finishing, ductwork, and plumbing fixture install in progress. Placement for permanent casino level non-specialty lighting is in progress. Ceiling completion on the BOH level is approx. 75%. - Hotel: Stud framing and door frame install almost completed. Electrical rough-in on T-19. Plumbing rough-in progressing on T-20 and plumbing risers completed through T-24. Guestroom wall sheet rock starting on T-15. Ceiling mud float currently on T-21. Non-guestroom drywall install T-23. Elevators #1 & 2 frame build in progress, approx. 40% completed. Guestroom wall tile install on T-5. | G3: low | H3: medium | L3: =SUM(I3:K3) -> 0 | N3: =IFERROR(M3-L3,"0") -> 0 | O3: =IFERROR((M3-L3)/L3,"No Input") -> No Input | T3: =DAYS360(R3,S3) -> 0
B4: MARDI GRAS
A5: 1 | B5: Hotel renovation and Laundry Room #08487 | C5: 08487 | D5: Greg Dauberger | E5: Lobby Renovation - Project close out in process. All major contracts closed out. - Elevator Signage ordered 3 week lead time - Shower goosnecks - Awaiting schedule update for order and replacement by local team. - All patio furniture delivered. Replacement bases for umbrellas on order. Warranty chairs have been selected and are on order. Will advise on delivery. - TV feeds are scrambled in lobby and bridge. Local IT team has a proposal to resolve the issue - moving away from analog system to a system that has a box at each TV - In discussion with property on potential completion/added scope items. | F5: Lobby Renovation - Project close out in process. - Directional signage installed, Registration signage installed. Elevator Signage ordered - 72 rooms will need Showerhead & Gooseneck replacements. Materials have been ordered by Mardi Gras Facilities team. 6-week lead time. Awaiting schedule for replacement by local team. - Rear patio furniture and umbrellas have been ordered. Deliveries have begun to arrive. - TV feeds are scrambled in lobby and bridge | G5: low | H5: low | I5: 75747 | J5: 759539 | K5: 13486196 | L5: 14321482 | M5: 14321482 | N5: =IFERROR(M5-L5,"0") -> 0 | O5: =IFERROR((M5-L5)/L5,"No Input") -> 0 | P5: 45566 | Q5: 45566 | R5: Rooms - 3/11/2025 Lobby - 11/12/2025 | S5: Rooms - 3/26/2025 Lobby - 11/12/2025 | T5: =DAYS360(R5,S5) -> #VALUE!
A6: 1 | B6: Mardi Gras Guest Restrooms | C6: 08673 | D6: John Kolkowski | E6: - Closing out - Final invoice for general contractor approved for payment. Awaiting update on architects final invoice. | F6: - Restroom remodel complete. All fixtures have been changed to the correct finish. Closing out. | I6: 42000 | J6: 2457096 | K6: 0 | L6: =Table3[[#This Row],[A & E / Pre-Con Capp]]+Table3[[#This Row],[Construction Capp]]+Table3[[#This Row],[Add-CAPP (Cumulative)]] -> 2499096 | M6: 2330078 | N6: =IFERROR(M6-L6,"0") -> -169018 | O6: =IFERROR((M6-L6)/L6,"No Input") -> -0.067631656 | P6: 45839 | Q6: 45839 | R6: 46111 | S6: 46210 | T6: =DAYS360(R6,S6) -> 97
B7: Mardi Gras Sports Bar Renovation | C7: 08688 | D7: Tim Brown / John Kolkowski | E7: - PSCP Budget $2M: SD Construction Estimate $1.6M - Construction being pushed to 2027. Will complete design in 2026 after Cafe is redesigned. | F7: - PSCP Budget $2M: SD Construction Estimate $1.4M | I7: 135300 | J7: 0 | K7: 0 | L7: =Table3[[#This Row],[A & E / Pre-Con Capp]]+Table3[[#This Row],[Construction Capp]]+Table3[[#This Row],[Add-CAPP (Cumulative)]] -> 135300 | M7: 0 | N7: =IFERROR(M7-L7,"0") -> -135300 | O7: =IFERROR((M7-L7)/L7,"No Input") -> -1 | P7: 46295 | Q7: 45839 | R7: TBD | S7: TBD | T7: =DAYS360(R7,S7) -> #VALUE!
B8: Mardi Gras Cafe Renovation | C8: 08714 | D8: Tim Brown / John Kolkowski | E8: - PSCP Budget $750K - Revised Construction ROM $3.03M - Doesn't include Bar FSE - ANF issued SD Set 9/11 - sent to Singer for equipment layout and revised pricing | F8: - PSCP Budget $750K - Revised SD Construction Estimate $2.7M - Agsten provided a revised Construction Estimate 8/21 - ANF to issue a revised SD set by 9/11 | I8: 127600 | J8: 0 | K8: 0 | L8: =Table3[[#This Row],[A & E / Pre-Con Capp]]+Table3[[#This Row],[Construction Capp]]+Table3[[#This Row],[Add-CAPP (Cumulative)]] -> 127600 | M8: 2100000 | N8: =IFERROR(M8-L8,"0") -> 1972400 | O8: =IFERROR((M8-L8)/L8,"No Input") -> 15.45768 | P8: 46295 | Q8: 45839 | R8: TBD | S8: TBD | T8: =DAYS360(R8,S8) -> #VALUE!
B9: Mardi Gras Steakhouse Renovation | C9: 08689 | D9: Tim Brown / John Kolkowski | E9: - PSCP Budget $1M - Design CAPP has been approved - Construction being pushed to 2027. Will complete design in 2026 after Cafe is redesigned. | F9: - PSCP Budget $1M - Design CAPP has been approved - Property wishes to hold until 2027 and prioritize the SB and Cafe. | I9: 22275 | J9: 0 | K9: 0 | L9: =Table3[[#This Row],[A & E / Pre-Con Capp]]+Table3[[#This Row],[Construction Capp]]+Table3[[#This Row],[Add-CAPP (Cumulative)]] -> 22275 | M9: 1400000 | N9: =IFERROR(M9-L9,"0") -> 1377725 | O9: =IFERROR((M9-L9)/L9,"No Input") -> 61.85073 | P9: 46387 | Q9: 45839 | R9: TBD | S9: TBD | T9: =DAYS360(R9,S9) -> #VALUE!
B10: GATE CITY/NASHUA RESORT
A11: 1 | B11: Gaming Expansion | C11: 08649 | D11: Tim Brown | E11: - IC approved $144M budget on 8/25 - Completion of Casino scheuduled for Feb 2028 - CUP has been unanimously approved - Early sitework permits approved - Design kickoff with Suffolk occured 08/10 - budget check ongoing through design completion | F11: - Design was unpaused on 07/08, SH has submiited their plan to restart design through a series of Owner's meetings through Aug - Arc Bulider's preconstruction agreement has been terminated - SD Estimate indicates a ~22M increase to budget based on newly required scope by AHJ, unforeseen escalations, and new scope items - CUP recommendation for approval pending city engineer's acceptance of traffic modeling - Next hearing date 8/6 - Early sitework permits approved | G11: low | H11: low | I11: 291650 | J11: 19286517 | K11: 0 | L11: 99343000 | M11: 99343000 | P11: 45672 | Q11: 45672 | R11: 46660 | S11: 46660 | T11: 0
A12: 1 | B12: Fitness Center Renovation | C12: 08650A | D12: Tim Brown | E12: - Permit in hand - Arc Builders to provide a draft contact for ~$530k - Scheduled completion on 12/31 | F12: - Permit in hand - Tendered pricing was +50% over budget primarily due to new electrical systems. Awaiting response from engineers on basis of design | G12: low | H12: low | I12: 99000 | J12: 0 | K12: 0 | L12: 99000 | M12: 502191 | P12: 46028 | Q12: 46028 | R12: 46174 | S12: 46174 | T12: 0
A13: 1 | B13: Exterior Lighting & Emerg. Gen. Relocation | C13: 08651 | D13: Tim Brown | E13: - Recommendations set for replacing the existing 450A system with a 2000A system. - Lead Time 50 weeks - Investigating options to provide back-up power on all casino. | F13: - Pricing submitted 3/18 with recommendations set for replacing the existing 450A system with a 2500A system. - Lead Time 50 weeks - Investigating options to provide back-up power on all casino. | G13: low | H13: low | I13: 0 | J13: 0 | K13: =SUM(Table3[[#This Row],[A & E / Pre-Con Capp]:[Construction Capp]]) -> 0 | L13: 0 | M13: TBD | P13: TBD | Q13: TBD | R13: TBD | S13: TBD
A14: 1 | B14: Electrical Switchgear Replacement | C14: 08653 | D14: Tim Brown | E14: - Recommendations set for replacing the existing 450A system with a 2000A system. - ARC finalizing full proposal, due 4/17 | F14: - Pricing submitted 3/18 with recommendations set for replacing the existing 450A system with a 2500A system. - ARC finalizing full proposal, due 4/17 | G14: low | H14: low | I14: 0 | J14: 0 | K14: =SUM(Table3[[#This Row],[A & E / Pre-Con Capp]:[Construction Capp]]) -> 0 | L14: 0 | M14: 1200000 | P14: TBD | Q14: TBD | R14: TBD | S14: TBD
B15: WHEELING ISLAND
A16: 1 | B16: Wheeling Island - Buffet | C16: 08523 | D16: John Kolkowski | E16: THA issued multiple options for buffet top specification. Samples of each being sent to Kim for review - to arrive 9/15 | F16: THA working with Cambria on specification, Cambria had concerns with heat lamp spread and thermal cycles. THA investigating additional materials | G16: low | H16: low | I16: 273042 | J16: 2539645 | K16: 0 | L16: =SUM(I16:K16) -> 2812687 | M16: 2812687 | N16: 0 | O16: =IFERROR((M16-L16)/L16,"No Input") -> 0 | P16: 45176 | Q16: 45530 | R16: 45600 | S16: 45603 | T16: 3
A17: 1 | B17: Wheeling Island Hotel Remodel | C17: 08593 | D17: John Kolkowski | E17: -Tile on site for elevator lobbies and corridor tile at Wheeling for review against carpet. - Looking at replacement wheels for housekeeping carts | F17: -Tile on site for elevator lobbies and corridor tile at Wheeling for review against carpet. - Looking at replacement wheels for housekeeping carts | G17: low | H17: low | I17: 160000 | J17: 10034401 | K17: 0 | L17: =SUM(I17:K17) -> 10194401 | M17: 10194401 | N17: =IFERROR(M17-L17,"0") -> 0 | O17: =IFERROR((M17-L17)/L17,"No Input") -> 0 | P17: 45887 | Q17: 45887 | R17: 46022 | S17: 46072 | T17: =DAYS360(R17,S17) -> 49
A18: 1 | B18: Wheeling Island - Public Restrooms | C18: 08656 | D18: John Kolkowski | E18: - Restroom A - toilet Partions will be swapped out for correct laminate 9/14 | F18: - Restroom C - Restrooms turning over Thursday 9/3 - Restroom A - toilet Partions will be swapped out for correct laminate 9/8 and 9/9 | G18: low | H18: low | I18: 56500 | J18: 2401100 | K18: 0 | L18: =SUM(I18:K18) -> 2457600 | M18: 2457600 | N18: =IFERROR(M18-L18,"0") -> 0 | O18: =IFERROR((M18-L18)/L18,"No Input") -> 0 | P18: 46048 | Q18: 46048 | R18: 46269 | S18: 46269 | T18: =DAYS360(R18,S18) -> 0
A19: 1 | B19: Wheeling Island - Lobby Remodel | C19: 08719 | D19: John Kolkowski | E19: Received pricing back from Buck $1.9M - does not include winners wall or acrylic features in the waterfall to replace the plants. Setting up review meeting with Kim this week | F19: Final CD's issued 7/25 - sent to Buck for pricing back by 9/4 | G19: low | H19: low | I19: 50000 | J19: 0 | K19: 0 | L19: =SUM(I19:K19) -> 50000 | M19: 50000 | N19: =IFERROR(M19-L19,"0") -> 0 | O19: =IFERROR((M19-L19)/L19,"No Input") -> 0 | P19: 46204 | Q19: 46204 | R19: 46296 | S19: 46296 | T19: =DAYS360(R19,S19) -> 0
B20: Concrete Pathways | C20: 08733 | D20: John Kolkowski | E20: Start date 9/8 - approx. 12 week duration | F20: Start date 9/8 - approx. 12 week duration | G20: low | H20: low | I20: 0 | J20: 516000 | K20: 0 | L20: =SUM(I20:K20) -> 516000 | M20: 500000 | N20: =IFERROR(M20-L20,"0") -> -16000 | O20: =IFERROR((M20-L20)/L20,"No Input") -> -0.031007752 | P20: 46273 | Q20: 46273 | R20: 46371 | S20: 46371 | T20: =DAYS360(R20,S20) -> 0
B21: Elevator Modernization | C21: 08732 | D21: John Kolkowski | E21: *Specs done end of next week 8/21 *Page turn on 8/31 to run through specs and scope before going out to bid *Target award date to release a contractor 9/28 – ~4 contractors bidding | F21: *Specs done end of next week 8/21 *Page turn on 8/31 to run through specs and scope before going out to bid *Target award date to release a contractor 9/28 – ~4 contractors bidding | G21: low | H21: low | I21: 48195 | J21: 0 | K21: 0 | L21: =SUM(I21:K21) -> 48195 | M21: 1800000 | N21: =IFERROR(M21-L21,"0") -> 1751805 | O21: =IFERROR((M21-L21)/L21,"No Input") -> 36.348273 | P21: TBD | Q21: TBD | R21: TBD | S21: TBD | T21: =DAYS360(R21,S21) -> #VALUE!
A22: 1 | B22: Buffet Walk-In Freezer | C22: 08726 | D22: John Kolkowski | E22: Freezer is up and running. Closing out. | F22: Freezer is up and running. Closing out. | G22: low | H22: low | I22: 0 | J22: 400000 | K22: 0 | L22: =SUM(I22:K22) -> 400000 | M22: 400000 | N22: =IFERROR(M22-L22,"0") -> 0 | O22: =IFERROR((M22-L22)/L22,"No Input") -> 0 | P22: 46174 | Q22: 46168 | R22: 46234 | S22: 46239 | T22: =DAYS360(R22,S22) -> 5
B23: EMBER BRAND
A24: 1 | B24: Rewards Signage Change Out | C24: 63543 | D24: John Kolkowski | E24: -Received proposal from Applied Media for Southland parking garage signage. Steve Martin is reviewing with others to determine if we want Ember Rewards on the signage or something more generic like "VIP Parking" - PSC $395k approved for 2026 between various projects - D&C costs $115k to date. | F24: -Applied media surveyed Southland parking garage. Scope and proposal to DNC by 8/21 - PSC $395k approved for 2026 between various projects - D&C costs $115k to date. | G24: low | H24: low | I24: 0 | J24: 166600 | K24: 0 | L24: =SUM(I24:K24) -> 166600 | M24: 115000 | N24: =IFERROR(M24-L24,"0") -> -51600 | O24: =IFERROR((M24-L24)/L24,"No Input") -> -0.30972389 | P24: TBD | Q24: TBD | R24: 46204 | S24: 46204 | T24: =DAYS360(R24,S24) -> 0
B25: Ember Brand Standards | C25: TBD | D25: Tim Brown | E25: - IIG was kicked off on 9/2, stakeholder meetings with Marketing schedule for the week of 9/7 - AddCap to be submitted for the entire design ~$250k | F25: - RFQ responses for Brand Standards has been presented with Gensler and IIG selected for RFP - New Cap to be submitted for the entire design in conjunction with the Finger Lakes refresh - Solicitation from the following firms: Gensler, IIG, SixteenFifty, TBE, JCJ, HBG, WATG
B26: FINGER LAKES GAMING
A27: 1 | B27: Smoking Patio | C27: 08660 | D27: John Kolkowski | E27: *Screen replacement Letter with Chris for submission to NYSDOH this week *Closing out financials | F27: *JCJ prepared new letter for NYSDOH approval of new screens - airflow is better than original and frames are the same dimension, should be no issue. *Letter with Chris for submission to NYS *Closing out financials | G27: low | H27: low | I27: 235000 | J27: 3939150 | K27: 913507 | L27: =SUM(I27:K27) -> 5087657 | M27: =4992127.21+50000 -> 5042127.2 | N27: =IFERROR(M27-L27,"0") -> -45529.79 | O27: =IFERROR((M27-L27)/L27,"No Input") -> -0.0089490683 | P27: 45908 | Q27: 45936 | R27: 46118 | S27: 46167 | T27: =DAYS360(R27,S27) -> 49
B28: Casino Carpet | D28: Tim Brown | E28: - Project paused until a Brand Standard has been established with the Ember Brand. - New Cap to be submitted for the entire design refresh of the Casino. | F28: - Budget source to fall in line with state supplemental OPEX fund. - Design Concepts ready for 4/29 leadership review - Strike offs will be ordered once carpet design has been narrowed to two options. | G28: low | H28: low | L28: =SUM(I28:K28) -> 0 | N28: =IFERROR(M28-L28,"0") -> 0 | O28: =IFERROR((M28-L28)/L28,"No Input") -> No Input | T28: =DAYS360(R28,S28) -> 0
B29: SOUTHLAND
A30: 1 | B30: Expansion Master Planning | C30: 08706 | D30: Tim Brown | E30: - Meeting to prepare pro forma on current development plans scheduled for 8/7. - All design efforts paused pending internal review of estimates - Estimates received for master planning and concept options. Estimates for operational and owner direct fees under development. - City infrastructure has limiting capacity and will need to be upgraded to service the masterplan. | F30: - Master Planning options now include the removal of the existing racetrack. - Additional options were requested to enhance the arrival experience. Original completion date for Master plan and Concept Design will extend beyond 4/10. - Marketing as requested new signage for gaming loyalty project to be implemented by 5/1 (all properties) - ARC will provide estimates for final Masterplan Options, needs 6 weeks to complete the effort, target mid-May - Cross Project Stakeholder Milestones - Initial concepts Mar 6 - Final design May 8 (was 4/10) | G30: low | H30: low | I30: 299775 | J30: 0 | K30: 0 | L30: 299775 | M30: 299775 | P30: 45991 | Q30: 46030 | R30: TBD | S30: TBD
A31: 1 | B31: Ignite Steak House Refresh | C31: TBD | D31: Tim Brown | E31: - All design efforts paused pending internal review of estimates - Estimates received for master planning and concept options. Estimates for operational and owner direct fees under development. | F31: - ARC will provide estimates for final Concept Options, needs 6 weeks to complete the effort, target mid-May. - Concept Package complete. | G31: low | H31: low | L31: 0 | M31: 0 | P31: 45991 | Q31: 46030 | R31: TBD | S31: TBD
A32: 1 | B32: High Limits/Destinations Refresh | C32: TBD | D32: Tim Brown | E32: - All design efforts paused pending internal review of estimates - Estimates received for master planning and concept options. Estimates for operational and owner direct fees under development. | F32: - ARC will provide estimates for final Concept Options, needs 6 weeks to complete the effort, target mid-May. - Concept Package complete. | G32: low | H32: low | L32: 0 | M32: 0 | P32: 45991 | Q32: 46030 | R32: TBD | S32: TBD
A33: 1 | B33: Charred Oak Bourbon Bar Refresh | C33: TBD | D33: Tim Brown | E33: - All design efforts paused pending internal review of estimates - Estimates received for master planning and concept options. Estimates for operational and owner direct fees under development. | F33: - ARC will provide estimates for final Concept Options, needs 6 weeks to complete the effort, target mid-May. - Concept Package complete. | G33: low | H33: low | L33: 0 | M33: 0 | P33: 45991 | Q33: 46030 | R33: TBD | S33: TBD
A34: 1 | B34: The Grind/Seasons Cafe Refresh | C34: TBD | D34: Tim Brown | E34: - All design efforts paused pending internal review of estimates - Estimates received for master planning and concept options. Estimates for operational and owner direct fees under development. | F34: - ARC will provide estimates for final Concept Options, needs 6 weeks to complete the effort, target mid-May. - Concept Package will incorporate new input from TX Eatzi concept. | G34: low | H34: low | L34: 0 | M34: 0 | P34: 45991 | Q34: 46030 | R34: TBD | S34: TBD
A35: 1 | B35: Hotel FF&E & Low Voltage | C35: TBD | D35: Tim Brown | E35: - All design efforts paused pending internal review of estimates - Estimates received for master planning and concept options. Estimates for operational and owner direct fees under development. | F35: - ARC will provide estimates for final Concept Options, needs 6 weeks to complete the effort, target mid-May. . - Concept Package complete. | G35: low | H35: low | L35: 0 | M35: 0 | P35: 45991 | Q35: 46030 | R35: TBD | S35: TBD
B36: CENTRAL CITY
A37: 1 | B37: New Construction Complex | C37: Non-Capital | D37: Greg Dauberger | E37: - DNC has suspended interaction with USGPD and CC vendors pending negotiations with USGPD on Management Agreement. - Project team is on hold. | F37: - DNC has suspended interaction with USGPD and CC vendors pending negotiations with USGPD on Management Agreement. - Project team is on hold. | G37: low | H37: low | I37: N/A | J37: N/A | K37: N/A | L37: N/A | M37: 850000000 | P37: TBD | Q37: TBD | R37: 47848 | S37: 47849
A38: =SUM(A1:A37) -> 21 | B38: TOTAL | I38: =SUM(I1:I37) -> 1916084 | J38: =SUM(J1:J37) -> 42500048 | K38: =SUM(K1:K37) -> 14399703 | L38: =SUM(L1:L37) -> 138580668 | M38: =SUM(M1:M37) -> 9.9486834e+08 | N38: =SUM(N1:N37) -> 4684482.2 | O38: =SUM(O1:O37) -> 112.23937

Sheet PARKS
A1: Count | B1: Project Name | C1: CAPP # | D1: PM | E1: Project Update | F1: Previous Week Update | G1: Budget Risk | H1: Schedule Risk | I1: A & E / Pre-Con Capp | J1: Construction Capp | K1: Add-CAPP (Cumulative) | L1: Total Approved Budget | M1: Anticipated Final Cost | N1: Budget / Final Cost Variance | O1: % Variance | P1: Original Start Date | Q1: Current Start Date | R1: Original Turnover Date To Ops | S1: Current Turnover Date To Ops | T1: Duration Change | U1: Column1
B2: CACTUS MOON
B3: Waybound Phase I | C3: 08705A | D3: Bill Nielsen | E3: Met with the proposed architect - DTA and Blue Horse to review the project. Plan is now to use the existing buildings as the event spaces with the addition of new space for F&B. A new Commons will be built on the current pad adjacent to the house. Ops is still working through the number of casitas needed. | F3: Work continues on civil designs and entitlement phase. Meeting with the proposed architect the week of 8/24 to review scope of work at the Commons buildings and the look and feel of the Event Center and Havens. | G3: low | H3: low | I3: 281660 | J3: 0 | K3: 0 | L3: =SUM(I3:K3) -> 281660 | M3: 0 | P3: TBD | Q3: TBD | R3: TBD | S3: TBD | T3: =DAYS360(R3,S3) -> #VALUE!
B4: ESTES PARK RIDGELINE
A5: 1 | B5: Holiday Inn PIP #08563 | C5: 08563 | D5: John Kolkowski | E5: Painting complete. Trash enclosure & ramp complete, gates delayed. Anticipated delivery 9/7 Woodworks West is putting together numbers after their site visit last week. Anticipate a full budget by 9/3 | F5: Painting complete. Trash enclosure starting this week, targeting 8/21 completion. Woodworks West is putting together numbers after their site visit last week. Anticipate a full budget by 8/28 | G5: low | H5: low | I5: 446800 | J5: 4061567 | K5: 105000 | L5: =SUM(I5:K5) -> 4613367 | M5: 4613367 | N5: =IFERROR(M5-L5,"0") -> 0 | O5: 0 | P5: 45870 | Q5: 45870 | R5: 46174 | S5: 46204 | T5: =DAYS360(R5,S5) -> 30
B6: GRAY WOLF LODGE
A7: 1 | B7: Interior renovation #08611 | C7: 08611 | D7: John Kolkowski | E7: *Addt'l pool mural delivery scheduled for 9/2 *Reviewing outstanding punchlist items with WWW this week. Suspended due to lack of access to guestrooms. Scheduling another walk through at end of season with WWW and ops *Simden requesting dining furniture in two suites. With THA for selection | F7: Add CAPP approved. *Lobby soft seating installed *Lamps being unboxed and installed in rooms progressively *Request for an additional mural in the pool, ordered 7/27 | I7: 89570 | J7: 5210604 | K7: 98342 | L7: =SUM(I7:K7) -> 5398516 | M7: =85781+5300174+2561 -> 5388516 | N7: =IFERROR(M7-L7,"0") -> -10000 | O7: 0 | P7: 46023 | Q7: 46023 | R7: 46185 | S7: 46188 | T7: =DAYS360(R7,S7) -> 3
B8: GENEVA LODGE
B9: Rooms Renovation / FFE | C9: NON CAPP | D9: Bill Nielsen | E9: FFE number received from Purchasing Dimensions. Final tweaks to be complete week of 9/14 and presented to County. Drawings showing final scope (eliminating tub replacement) due 9/14. GC bids due soon. | F9: Designs have been tentatively approved with some exceptions by the client. Awaiting firm FFE numbers from Purchasing Dimensions on 9/11. PO's will then be cut for the model room. Also expecting numbers from local GC's. | I9: 0 | J9: 0 | K9: 0 | L9: 5500000 | M9: 5500000 | N9: =IFERROR(M9-L9,"0") -> 0 | O9: 0 | P9: TBD | Q9: TBD | R9: 46508 | S9: 46508 | T9: =DAYS360(R9,S9) -> 0
B10: NORTH YELLOWSTONE
B11: Explorer Cabins | C11: 08715 | D11: Bill Nielsen | E11: ROM has been distributed to stakeholders. Awaiting direction. | F11: ROM to be received the week of 8/31. | I11: 11000 | J11: 52000 | K11: 0 | L11: =SUM(I11:K11) -> 63000 | M11: 13922000 | N11: =IFERROR(M11-L11,"0") -> 13859000 | O11: 0 | P11: TBD | Q11: TBD | R11: TBD | S11: TBD | T11: =DAYS360(R11,S11) -> #VALUE!
B12: TRACT M HOTEL
B13: Titusville - Tract M | C13: 08658 | D13: Bill Nielsen | E13: Awaiting direction. Residence Inn may be back in the picture | F13: Now looking at Homewood Suites option. 120 keys with 5000 square foot Events Center. | I13: 0 | J13: 0 | K13: 0 | L13: =SUM(I13:K13) -> 0 | M13: 0 | N13: =IFERROR(M13-L13,"0") -> 0 | O13: =IFERROR((M13-L13)/L13,"No Input") -> No Input | T13: =DAYS360(R13,S13) -> 0
B14: TENAYA LODGE
A15: 1 | B15: Waybound Renovation | C15: 08661 | D15: Bill Nielsen | E15: Pool repairs to take place 9/23-9/25. FP repairs to start once best remedy is decided on by contractor. | F15: Closing out invoices. Pricing some additional Operations requests. Completing remaining punchlist items. | G15: medium | H15: Low | I15: 200000 | J15: 5300000 | K15: 284000 | L15: =SUM(I15:K15) -> 5784000 | M15: 5784000 | N15: =IFERROR(M15-L15,"0") -> 0 | O15: =IFERROR((M15-L15)/L15,"No Input") -> 0 | P15: 45962 | Q15: 46003 | R15: 46111 | S15: 46175 | T15: =DAYS360(R15,S15) -> 62
B16: WEST YELLOWSTONE
A17: 1 | B17: Explorer Cabins Clubhouse | C17: 08529 | D17: John Kolkowski | E17: Roof modifications being completed by 8/28 from CT. Issuing 100% CD's on 9/3. Blue Heron Design can not bid due to timing. Woodworks West still working on pricing. | F17: Finalizing roof framing adjustments & interior FF&E selections. Asking for pricing back from contractors by 9/15 | I17: 132350 | J17: 0 | K17: 0 | L17: =SUM(I17:K17) -> 132350 | M17: 132350 | N17: =IFERROR(M17-L17,"0") -> 0 | O17: 0 | P17: 45962 | Q17: 45962 | R17: 46204 | S17: 46204 | T17: =DAYS360(R17,S17) -> 0
B18: YELLOWSTONE GENERAL STORES
A19: 1 | B19: Old Faithful Dorm - Roof, Refurb and Fire Rating | C19: 08495 | D19: Chynna Barron | E19: CB Site Visit for all OF Projects on 9/17. Final walk with NPS rescheduled for week of 9/22 due to NPS OOO from 9/10 - 9/18. Final cleaning and furniture install in progress in addition. Demobilization in progress around dormitory. Compliance has asked that we do not paint fire lines. Schedule update for fall work in progress. Punch items remain in dorm rooms which are occupied. | F19: CB Site Visit for all OF Projects on 8/27 to ensure preparation is complete for final walk. Final walk with NPS scheduled for Thursday, 9/9. Julie may have additional questions from Sayer, NPS Volunteer Historical Arch. RR Taylor has re-bid paint scope which will be revised by based on NPS feedback regarding painting of fire lines in building addition. Compliance has asked that we do not paint fire lines. Schedule update for fall work in progress. Punch items remain in dorm rooms which are occupied. | G19: low | H19: low | I19: 250000 | J19: 4021385 | K19: 353954 | L19: =SUM(I19:K19) -> 4625339 | M19: 4122787 | N19: =IFERROR(M19-L19,"0") -> -502552 | O19: =IFERROR((M19-L19)/L19,"No Input") -> -0.10865193 | P19: 45505 | Q19: 45909 | R19: 45747 | S19: 46127 | T19: =DAYS360(R19,S19) -> 375
A20: 1 | B20: Old Faithful Upper G.S. - Refurb and Fire Protection Replacement | C20: 08496 | D20: Chynna Barron | E20: Walls appear to have years of coverage from cleaning products / oils. Moonlight Painting has chose to not bid on this work. R&R assessing manpower to complete refinishing in-house. Cost due by 9/16. Partition replacements will take place this week. CB site visit will oversee progress and quality of partition replacements. Closure schedule to be provided by 9/15. | F20: Final walk with NPS scheduled for Thursday, 9/9. RR Taylor Reviewing scope for intumescent paint with RR on 8/24. Walls appear to have years of coverage from cleaning products / oils. Alternative methods of cleaning have been provided by Moonlight Painting. Partition replacements tentatively scheduled for 9/14. Framing at riser room to begin 9/14. | G20: low | H20: low | I20: 120000 | J20: 3972534 | K20: 0 | L20: =SUM(I20:K20) -> 4092534 | M20: 4074560 | N20: =IFERROR(M20-L20,"0") -> -17974 | O20: =IFERROR((M20-L20)/L20,"No Input") -> -0.0043919 | P20: 45593 | Q20: 45909 | R20: 45747 | S20: 46127 | T20: =DAYS360(R20,S20) -> 375 | AA20: IMG_3340.JPG
B21: Old Faithful Upper General Store - Retail Improvements | C21: 08718 | D21: Chynna Barron | E21: Store open on 4/24. | F21: Store open on 4/24. | G21: low | H21: low | I21: 0 | J21: 585601 | K21: 0 | L21: =SUM(I21:K21) -> 585601 | M21: 585601 | N21: =IFERROR(M21-L21,"0") -> 0 | O21: =IFERROR((M21-L21)/L21,"No Input") -> 0 | P21: 45725 | Q21: 45725 | R21: 46127 | S21: 46122 | T21: =DAYS360(R21,S21) -> -5
A22: 1 | B22: Old Faithful Upper - Ice Cream Parlor | C22: 08500 | D22: Chynna Barron | E22: Ice Cream open on 4/24. Safe removal to take place in after season end / store close. | F22: Ice Cream open on 4/24. Safe removal to take place in fall. Updated schedule for fall work being updated. | G22: low | H22: low | I22: 125000 | J22: 963029 | K22: 0 | L22: =SUM(I22:K22) -> 1088029 | M22: 1011025 | N22: =IFERROR(M22-L22,"0") -> -77004 | O22: =IFERROR((M22-L22)/L22,"No Input") -> -0.070773849 | P22: 45607 | Q22: 45817 | R22: 45747 | S22: 46110 | T22: =DAYS360(R22,S22) -> 359 | AA22: 2.JPG
A23: 1 | B23: Canyon General Store - Roof & Seismic | C23: 08621 | D23: Chynna Barron | E23: Work on seismic investigation to restart once additional safety plan is provided. Due from Bauer on 9/16. Roof replacement to recommence on 10/5. Store closure for season on 10/11. | F23: ACM testing complete and all areas clear except under 10SF of caulking which will be bagged and removed. New safety plan submitted and reviewed by NPS. Revewing potential demolition night work schedule with Erin B on 8/24 before submitting to NPS. Night demo will allow work to continue sooner than October. | G23: low | H23: low | I23: 114000 | J23: 2062884 | K23: 0 | L23: =SUM(I23:K23) -> 2176884 | M23: 2176884 | N23: =IFERROR(M23-L23,"0") -> 0 | O23: =IFERROR((M23-L23)/L23,"No Input") -> 0 | P23: 45501 | Q23: 46104 | R23: 46003 | S23: 46206 | T23: =DAYS360(R23,S23) -> 201
A24: 1 | B24: Canyon Adventure - Convert to F&B | C24: 08574 | D24: Chynna Barron | E24: Final walk to be scheduled with Robbie. Punch list pending installation of standing-bar top and new door installation. | F24: 1872 is open. Interior sign has been installed. Decorative lighting delivery pending. Beams being repaired in store front. Glass for sneezeguard was damaged in delivery and will need second replacement. Tentative final walk with NPS on 9/8. | G24: low | H24: low | I24: 263100 | J24: 2590589 | K24: 0 | L24: =SUM(I24:K24) -> 2853689 | M24: 2852356 | N24: =IFERROR(M24-L24,"0") -> -1333 | O24: =IFERROR((M24-L24)/L24,"No Input") -> -0.00046711467 | P24: 45501 | Q24: 46104 | R24: 46003 | S24: 46179 | T24: =DAYS360(R24,S24) -> 174
A25: 1 | B25: Canyon New Dorm | C25: 08598 | D25: Chynna Barron | E25: NPS project review in progress and Facilities review of Design Report. Response from NPS on Design Report expected 9/14, per Julie O. | F25: Add CAPP approved. NPS project review in progress. Updated staging plans have been provided and the staging area has been taped of by PWC. As of 8/20 no further information is being requested from NPS biologists. Soil testing has been completed with preliminary findings from pXRF scans showing lead levels under EPA limits. The area around the existing dorm has shown higher levels which will be lined out in official report, with further guidance from NPS regarding removal. Pre-construction site-walk has been completed. Allied recalculating hydraulics based on NPS Fire Chief approved FDC / hydrant location. Updated calcs to be combined with design report and submitted on 8/24. Design report will be provided to NPS Facilities for signature on DEQ permit and then submitted to WY. DEQ contacts being called to discuss expediting. Exploring options for Winter 2027 work through the snow season. | G25: low | H25: low | I25: 500000 | J25: 16372100 | K25: 0 | L25: =SUM(I25:K25) -> 16872100 | M25: 16872100 | N25: =IFERROR(M25-L25,"0") -> 0 | O25: =IFERROR((M25-L25)/L25,"No Input") -> 0 | P25: 45501 | Q25: 46237 | R25: 46871 | S25: TBD | T25: =DAYS360(R25,S25) -> #VALUE!
A26: 1 | B26: Canyon General Store - Improvements | C26: 08575 | D26: Chynna Barron | E26: Additional retail scope information has been provided. Update to costs in progress by Bauer. | F26: Pending timeline for add CAPP submission. CAPP must be subitted as soon as possible in order to begin any fall work with Bauer. The full scope is anticipated to go past the normal opening date should demolition have to begin in spring 27 due to the size of scope. Updated costs with estimate of retail fixtures and a cash flow have been provided to Erin B. Pending full scope of fixture replacement from Wes and team in order for Bauer to update labor cost. | G26: low | H26: low | I26: 146100 | J26: 0 | K26: 0 | L26: =SUM(I26:K26) -> 146100 | M26: 3000000 | N26: =IFERROR(M26-L26,"0") -> 2853900 | O26: =IFERROR((M26-L26)/L26,"No Input") -> 19.533881 | P26: 45501 | Q26: 45989 | R26: 46003 | S26: 46505 | T26: =DAYS360(R26,S26) -> 496 | AA26: IMG_3428.JPG
A27: =SUM(A1:A25) -> 10 | B27: TOTAL | I27: =SUM(I4:I25) -> 2251820 | J27: =SUM(J4:J25) -> 45192293 | K27: =SUM(K4:K25) -> 841296 | L27: =SUM(L4:L25) -> 53785409 | M27: =SUM(M4:M25) -> 67035546 | N27: =SUM(N4:N25) -> 13250137 | T27: =DAYS360(R27,S27) -> 0

Sheet SS
A1: Count | B1: Project Name | C1: CAPP # | D1: PM | E1: Project Update | F1: Previous Week Update | G1: Budget Risk | H1: Schedule Risk | I1: A & E / Pre-Con Capp | J1: Construction Capp | K1: Add-CAPP (Cumulative) | L1: Total Approved Budget | M1: Anticipated Final Cost | N1: Budget / Final Cost Variance | O1: % Variance | P1: Original Start Date | Q1: Current Start Date | R1: Original Turnover Date To Ops | S1: Current Turnover Date To Ops | T1: Duration Change
A4: =SUM(A1:A3) -> 0 | B4: TOTAL | I4: =SUBTOTAL(109,I2:I3) -> 0 | J4: =SUM(J2:J3) -> 0 | K4: =SUM(K2:K3) -> 0 | L4: =SUM(L2:L3) -> 0 | M4: =SUM(M2:M3) -> 0 | N4: =SUM(N2:N3) -> 0
K6: `

Sheet DEAD DEVELOPMENT PROJECTS
A1: Project Name | B1: Initiative # | C1: Project Development Lead | D1: Project Scope/Description | E1: Weekly Update | F1: Status | G1: Request Date | H1: Requestor | I1: Deliverable Due Date | J1: Architect, Engineers, CM Consultants | K1: Food Service Design | L1: Design CAPP (Y/N) | M1: Subsidiary/Biz Dev Expense Total ($) | N1: Original Estimate | O1: Original Estimate Date | P1: Current Estimate | Q1: Current Estimate Date
A2: TRAVEL HOSPITALITY SERVICES
A3: LAX - Wahoo Fish Tacos Conversion | C3: Joe Quagliana | D3: Conversion of Wahoo To Big Chicken | E3: Kyle met with Chris A. on 10/26. Working with PID & Wasserstrom on pricing. | F3: Active | G3: 44848 | H3: Chris Agne | I3: 44883
A4: MSP - Smack Shack Conversion | C4: Joe Quagliana | D4: Converting Smack Shack to Northern Soul | E4: Rebranding space, reconfiguring FoH, swapping out some equipment. Waiting on airport approval of concept. | F4: Active | G4: 44811 | H4: Chris Chila | I4: 44862 | J4: Alliance? | K4: Wass | N4: 782000 | O4: 44842
A5: BOS - New Balance Conversion | B5: 08468 | C5: Joe Quagliana | D5: Convert New Balance to a Boston Team store | E5: Preliminary design and pricing complete. Mark M. submitting CAPP for approval. | F5: Complete | G5: 44819 | H5: Chris Chila | I5: 44867 | J5: Silhouette | N5: 124190 | O5: 44866
A6: Tucson | C6: Joe Quagliana | D6: Pricing for conversion of existing coffee to Starbucks and Midterm work. | E6: Developed estimate & shared it with Lovin Construction. Still need to adjust for Starbucks scope. | F6: Complete | G6: 44858 | H6: Chris Agne | I6: 44855 | N6: 1505000 | O6: 44803
A7: Tucson ADA issues | C7: Josh Santelli | D7: ADA violations | E7: Report was reviewed with Chirus Agne. THS is pricing new furniture and millwork modification. | F7: Active | G7: 44762 | I7: 44774
A8: Boston Commissary | B8: 08249 | C8: Mark Migliore | D8: Completion of commissary that was started by Petore in 2019. | E8: Revised pricing sent to TH on 8/29/22. Awaiting response/direction. | F8: Active | H8: Chris Chila | I8: 44727
A9: Austin - Mid Term Refresh | C9: Mark Migliore
A10: Charleston | C10: Josh Santelli | D10: D&C needs to capture scope. Tom meet Silhouette (Tara) to work areas. | E10: Meeting scheduled by THS for 11/4 to provide an internal update. | H10: Tom Waldron
A11: LAX - Wahoo Fish Tacos Conversion and Midterm | B11: 08475 | C11: Mark Migliore | D11: Conversion of Wahoo To Big Chicken and Midterm work at Habit & Earthbar | E11: Kyle from PID met with Chris A. on 10/26 and provided pricing. PID priced reduced scope and get closer to budget. | F11: Active | G11: 44848 | H11: Chris Agne | I11: 44945 | J11: Premier Interior Development | K11: Smith & Greene | N11: 1531000 | O11: 44895 | P11: 799964 | Q11: 44945
A12: SPORTSERVICE
A13: Target Field Stand 109 Market | C13: Joe Quagliana | D13: Convert existing concession to market | E13: Project on hold while team evaluates. | F13: Complete | G13: 44774 | H13: Pete Spike
A14: Atlanta Braves | C14: Joe Quagliana | D14: Book of Concepts | E14: HHL has completed renderings. Opinion of Cost complete. | F14: Complete | G14: 44595 | H14: Fattar | I14: 44818 | J14: HHL | N14: 26310000 | O14: 44819
A15: Bridgestone - Patron Club | C15: Joe Quagliana | D15: Remodel Patron Club | E15: Providing updated answers to clients questions. | F15: Complete | H15: Mike Geczi | I15: 44838 | J15: MSA | K15: A1 | N15: 6130000 | O15: 44782
A16: RedBull | C16: Joe Quagliana | D16: Book of Concepts | E16: In development | F16: Active | G16: 44637 | H16: Bob Thormeier | I16: 44774 | J16: MSA | K16: Yes
A17: RedBull Concessions | C17: Joe Quagliana | D17: Converting stands 128 & 133 to market concepts | E17: Pricing and schedule provided | F17: Complete | H17: Bob Thormeier | I17: 44763 | J17: MSA | N17: 2087000 | O17: 44763
A18: SLU | C18: Josh Santelli | D18: Book of Concepts | E18: Deliver in Q1 2024 per Dan Fetcho | F18: Active | G18: 44637 | H18: Tessa Lewis | I18: 44713 | J18: Shea
A19: Cleveland Guardians/Progressive Field | B19: 08438 | C19: Joe Quagliana | D19: Book of Concepts - concession/market | E19: Working through concepts with Rossetti | F19: Active | G19: 44715 | H19: Don Dierig | I19: 44896 | J19: Rossetti
A20: Busch Stadium | C20: Joe Quagliana | D20: Book of Concepts - concession/market | E20: DN team has decided to work with Populous. Call this week to finalize date for site visit. | F20: Active | G20: 44846 | H20: Dan Fetcho
A21: Prudential Center | C21: Joe Quagliana | D21: Working Gensler to provide renderings in a number of areas through the building. | E21: Renderings Complete | F21: Complete | G21: 44775 | H21: Don Dierig
A22: PARKS & RESORTS
A23: Shenandoah - Blackrock Guest Cabins | B23: 08444 | C23: Joe Quagliana | D23: Complete reconstruction of the Blackrock Cabins to now include 12 units | E23: Budget pricing provided by | F23: Complete | G23: 44849 | H23: Bill Nielson | I23: 44869 | J23: Stantec | N23: 4321000 | O23: 44872
A24: Squire Inn | C24: Joe Quagliana | D24: New property. PIP and other CAPP needs
A25: Yellowstone RFP | C25: Joe Quagliana
A26: Grand Canyon North Rim | C26: Joe Quagliana | D26: High level pricing for go/no go | E26: Working with Loven Contracting | F26: Dead | G26: 44854 | H26: Deb Ward | I26: 44860 | N26: 13581620 | O26: 44869
A27: West Yellowstone Holiday Inn PIP | B27: 08386 | C27: John K | D27: Corridor & common space | E27: Received proposal from Woodworks West. CSC to submit bid by end of November. FF&E budget to be finalized before end of Nov. | F27: Active | G27: 44501 | H27: Derek | I27: 45214
A28: Whitefish - Retaining Wall Repair | B28: 08455 | C28: Mark Migliore | D28: Structurally reinforce or replace existing retaining wall to prevent further undermining of parking lot | E28: Preliminary drawings for pricing are running a week behind. Will have next week. Budgeting of those drawings is targeted for 11/24. | G28: 44593 | H28: Pete Donau
A29: Westin Buffalo | B29: 08400 | C29: Joe Quagliana | D29: Renovate rooms - 2 sample rooms released. May have to phase to fit within budget. Add CAPP required to complete sample rooms. | E29: Model rooms complete and over budget. Looking to get down to $4.2M | G29: 44515 | H29: Derek
A30: Ridgeline at Estes Window Replacement | B30: 08452 | C30: Mark Migliore | D30: Replace all windows of the hotel | E30: The completion of drawings is delayed. We will have an 80% set this Friday and complete set by the end of next week. That pushes are schedule approximately 3 days. The unit has asked for a budget on new window treatments. That budget was presented to Parks. Awaiting a response | H30: Lance Wellwood
A31: Camp Hale - Wedding Pavilion | B31: 08455 | C31: Josh Santelli | D31: New location in Vale CO. Creation of a wedding pavilion to replace tent that is currently there. | E31: Discussed 3 season pavilion and bathrooms to be added to the property, replacing the tent. Kick off meeting to be held on 10/31
A32: Tenaya - Pool Remodel | B32: 08454 | C32: Josh Santelli | D32: Brett Archer to send scope. Bids for work have already been received by the unit | E32: Design is over budget. Scope was reduced. Waiting on proposal to open CAPP for design and surveying.
A33: Wuksachi FFE - #08413 | B33: 08413 | C33: Bill Nielsen | D33: Project put on hold per P&R. Processing invoices from design team and FFE procurer. | E33: Scope of this project is in flux. Need direction from Parks on how to proceed. Add-CAPP will be required or new CAPP for additional construction scope and new refrigerators. | F33: low | G33: low | H33: 0 | I33: 0 | J33: 0 | K33: =SUM(H33:J33) -> 0 | L33: 600000 | O33: 44681 | P33: 44681 | Q33: 44713 | R33: 44713 | S33: =DAYS360(Q33,R33) -> 0
A34: Yellowstone Lake Service Station Repurpose | B34: 08497 | C34: John Bridges | D34: Design complete. On hold until 2026. | E34: 100% CDs provided to NPS for review and comment. | F34: On Hold | G34: 01.16.24 | H34: Lance Wellwood | I34: 12.31.26 | J34: Thomas Hamilton | K34: Yes | L34: 250000 | S34: =DAYS360(Q34,R34) -> 0
A35: Yellowstone Lake General Store Renovation | B35: 08501 | C35: John Bridges | D35: Removed from YGS projects list 01.12.24 | E35: On hold | F35: On Hold | G35: 01.16.24 | H35: Lance Wellwood | I35: 12.31.26 | J35: Thomas Hamilton | K35: Yes | L35: 100000 | S35: =DAYS360(Q35,R35) -> 0
A36: Yellowstone Lake Modular Housing | B36: 08498 | C36: John Bridges | D36: Design 60%. On hold until 2026. | E36: On hold. NPS is requiring the modular unit be installed in a new location (to be determined). | F36: On Hold | G36: 01.16.24 | H36: Lance Wellwood | I36: 12.31.26 | J36: Thomas Hamilton | K36: No | L36: 125000 | S36: =DAYS360(Q36,R36) -> 0
A37: GAMING
A38: Fingerlakes Hotel
A39: BBCC
A40: Two Kings - Master Plan | B40: 08312 | C40: Kris Irwin | D40: Potential development, casino, multiple hotels and other offerings. Phased construction. | E40: design work remains on hold with no additional work authorized by the Nation. | F40: Active | H40: Brian Hansberry
...

Sheet Design & Development
A1: Count | B1: Project Name | C1: Initiative # | D1: Project Development Lead | E1: Project Scope/Description | F1: Weekly Update | G1: Status | H1: Request Date | I1: Requestor | J1: Deliverable Due Date | K1: Architect, Engineers, CM Consultants | L1: Food Service Design | M1: Design CAPP (Y/N) | N1: Subsidiary/Biz Dev Expense Total ($) | O1: Original Estimate | P1: Original Estimate Date | Q1: Current Estimate | R1: Current Estimate Date
A2: =SUM(A5:A5) -> 1 | B2: SPORTSERVICE
B3: Comerica | D3: Joe Quagliana | E3: Developing budget for 3 seperate concepts. | F3: Draft estimate issued. Joe Slomski had some revisions. Revised estimate out tomorrow. | G3: Complete
B4: San Diego Baseball - Market Conversion | D4: Joe Quagliana | E4: Conversion of an existing concession to a market concept. | F4: Opinion of cost provided. Looks lie there may be multiple markets being converted this off season. | G4: Active | H4: 46106 | I4: Shawn Mattox | J4: 46107 | L4: Singer | O4: 1080000 | P4: 46107
A5: 1 | B5: Stadium of the Future (Jacksonville) | D5: Joe Quagliana | E5: Food Service layouts and portables for EverBank Stadium | F5: Call with team next week to discus portable design and next steps. Complete list of 123 portables by section number to coincide with drawing locations has been submitted. | G5: Active | H5: 45939 | I5: Shawn Mattox
A6: =SUM(#REF!) -> #REF! | B6: PARKS & RESORTS
B7: Yellowstone | D7: Joe Quagliana | E7: Various projects | F7: Gathering information | G7: Active | H7: 46094 | I7: Erin Benike | J7: 46084
B8: Kalaloch RFP | D8: Joe Quagliana | E8: Proposed development plans for RFP that drops later in 2026. | F8: Hobbs & Black has been engaged. Revised estimate submitted | G8: Complete | H8: 46164 | I8: Deb Ward | J8: 46219 | K8: Hobbs & Black | O8: 5519000 | P8: 46190 | Q8: 3504000 | R8: 46204
B9: Squire Resort | D9: Bill Nielsen | E9: Phase III of the PIP | F9: Received pricing from the GC. Need to make final decisions on SOW and release the designer. | G9: Active | H9: 46176 | I9: Michael Darrow | K9: Pending
B10: RV Park at West Yellowstone | D10: Chynna Barron | E10: Pending cost to complete design from A&E; PM has returned from OOO. Expected 9/18. PS Submitted to NPS. NPS will initiate white bark pine survey. Pending additional information on will-serve letter from West Yellowstone. Town engineer has stated that capacity is not a concern and is reviewing civil plans. | F10: Pending cost to complete design from A&E; PM OOO this week. PS Submitted to NPS. NPS will initiate white bark pine survey. Preparing RFP for construction to Jackson, Bauer, PWC. Pending additional information on will-serve letter from West Yellowstone. | G10: Active | I10: Erin Benike | K10: Pending
B11: Mammoth General Store / Mammoth Warehouse Rehab | D11: Chynna Barron | E11: THA and Mosaic completing bids. Mosaic site walk completed on 9/9. Bids due 9/18. | F11: THA and Mosaic completing bids. Meeting with Mosaic on site on 9/9 to answer any outstanding questions. | G11: Active | I11: Erin Benike | K11: Pending
A12: =SUM(#REF!) -> #REF! | B12: GAMING
B13: Surveillance Expansion | D13: John Kolkowski | E13: New Surveillance office space expansion onto roof adjacent to existing surveillance office | F13: On Hold until further notice per Dave Frankhouser 8/20 | G13: Hold | I13: Kim Florence
A14: =SUM(A15:A27) -> 11 | B14: PATINA
A15: 1 | B15: DTD Anaheim - Project Harbor (Izakaya concept) | C15: 08731 | D15: David Ruede | E15: Takeover of Ballast Point. Take Over of the space on 6/15/27 with 210 days to complete and get opened. | F15: Survey and design ideas kicked around on August 26th - very productive. Dan Brunn working on modeling the space and early design conceptual plans | G15: Active
A16: 1 | B16: Hencraft - Add Exterior Awning | D16: David Ruede | E16: Add a rigid awning to the side of the building to provide shelter to the remote Walk-In and Storage | F16: BRD sent in a Proposal ($18K). We will need drawings developed for permitting. David to build a budget for a CAPP to be done in September/October | G16: Active
A17: 1 | B17: Hundredfold BPV - Exterior Entry Enclosure | D17: David Ruede | E17: Add a Shelter in front of the exterior entry door to block the cold | F17: 2/26/2026 - Met with Gabriel Romero - Dream Awnings. Proposal is $14,898 (tax included) | G17: Active
A18: 1 | B18: Tutto | D18: David Ruede | E18: Major Remodel for Contract Extension. Expiration is 8/2029 | F18: Revisit end of year | G18: Active | H18: 45413 | I18: JK Kolaski | J18: tbd | K18: tbd | L18: Yes, will need. | M18: Yes, will need. | P18: 2026
A19: 1 | B19: Via Napoli | D19: David Ruede | E19: Major Remodel for Contract Extension - Expiration is 8/2029 | F19: Revisit end of year | G19: Active | I19: JK Kolaski | P19: 2026
B20: Via Napoli | D20: David Ruede | E20: Freezer Floor Repair | F20: Bruns submitted a proposal for $66, 850, plus $19,200 if this scope needs to be done in two phases. Working on a competitive price from Macon.
A21: 1 | B21: Via Napoli | D21: David Ruede | E21: Additional Exterior Walk-In Refrigerator with new refrigeration rack for new and existing exterior walk-ins. End 2026 Project. | F21: Bruns sent summary. Will then have a kick-off call with Singer. Set up a conference call - Jessica & Chef Costintino, Seth, Jason Petrino. Susan to set up. | G21: Hold | P21: 2026
A22: 1 | B22: Via Napoli | D22: David Ruede | E22: Enlarging Kitchen Door Opening from a 3' to 5' wide. | F22: Drawiings to be complete 7/6. Submit to CFTOD for permitting on 7/8. Receive permits on 8/5. Only then, place door order that has a 4 week lead time. Forecasted start in early September. Duration is 2-3 wks.
A23: 1 | B23: Via Napoli | D23: Jason | E23: Adding a 40' Connex Box to replace the old ones that Disney is taking away.
A24: 1 | B24: Lincoln Ristorante - East Dining Room/Bar & Lounge | C24: 8608 | D24: David Ruede | E24: Full Renovation that would include adding a bar to the East Dining Room and remove existing. | F24: Revisit end of year | G24: Active | H24: 45444 | I24: JK Kolaski | P24: 2026
A25: 1 | B25: DTD Naples & Napolini | D25: David Ruede | E25: Contract Expires 11/30/2029. | F25: Revisit end of year | G25: Active
B26: Nick & Stef's - NYC | D26: David Ruede | E26: Front of House Renovation with Lease Renewal | F26: Concept determined - Corteza House (Steakhouse). On Hold pending "statue negotiations" and/or whether MSG will be rebuilt elsewhere. | G26: Hold | H26: 45444 | I26: JK Kolaski | J26: tbd | K26: Ignisio | L26: Yes, will need. | M26: Yes, will need. | O26: 4623000 | P26: 45702 | R26: Summer 2027
A27: 1
B28: DELAWARE NORTH CORPORATE

Sheet CLOSED PROJECTS
A1: Project Name | B1: CAPP # | C1: PM | D1: Project Update | E1: Previous Week Update | F1: Budget Risk | G1: Schedule Risk | H1: A & E / Pre-Con Capp | I1: Construction Capp | J1: Add-CAPP (Cumulative) | K1: Total Approved Budget | L1: Anticipated Final Cost | M1: Budget / Final Cost Variance | N1: % Variance | O1: Original Start Date | P1: Current Start Date | Q1: Original Turnover Date To Ops | R1: Current Turnover Date To Ops | S1: Duration Change
S7: `
J15: `
